2021-04-10 17:09:49,273 ERROR: Exception on /user/aaron [GET] [in /home/aaron/dev/grovr/venv/lib/python3.8/site-packages/flask/app.py:1891]
Traceback (most recent call last):
  File "/home/aaron/dev/grovr/venv/lib/python3.8/site-packages/flask/app.py", line 2447, in wsgi_app
    response = self.full_dispatch_request()
  File "/home/aaron/dev/grovr/venv/lib/python3.8/site-packages/flask/app.py", line 1952, in full_dispatch_request
    rv = self.handle_user_exception(e)
  File "/home/aaron/dev/grovr/venv/lib/python3.8/site-packages/flask/app.py", line 1821, in handle_user_exception
    reraise(exc_type, exc_value, tb)
  File "/home/aaron/dev/grovr/venv/lib/python3.8/site-packages/flask/_compat.py", line 39, in reraise
    raise value
  File "/home/aaron/dev/grovr/venv/lib/python3.8/site-packages/flask/app.py", line 1950, in full_dispatch_request
    rv = self.dispatch_request()
  File "/home/aaron/dev/grovr/venv/lib/python3.8/site-packages/flask/app.py", line 1936, in dispatch_request
    return self.view_functions[rule.endpoint](**req.view_args)
  File "/home/aaron/dev/grovr/venv/lib/python3.8/site-packages/flask_login/utils.py", line 272, in decorated_view
    return func(*args, **kwargs)
  File "/home/aaron/dev/grovr/app/routes.py", line 79, in user
    return render_template('user.html', user=user, posts=posts)
  File "/home/aaron/dev/grovr/venv/lib/python3.8/site-packages/flask/templating.py", line 138, in render_template
    ctx.app.jinja_env.get_or_select_template(template_name_or_list),
  File "/home/aaron/dev/grovr/venv/lib/python3.8/site-packages/jinja2/environment.py", line 930, in get_or_select_template
    return self.get_template(template_name_or_list, parent, globals)
  File "/home/aaron/dev/grovr/venv/lib/python3.8/site-packages/jinja2/environment.py", line 883, in get_template
    return self._load_template(name, self.make_globals(globals))
  File "/home/aaron/dev/grovr/venv/lib/python3.8/site-packages/jinja2/environment.py", line 857, in _load_template
    template = self.loader.load(self, name, globals)
  File "/home/aaron/dev/grovr/venv/lib/python3.8/site-packages/jinja2/loaders.py", line 127, in load
    code = environment.compile(source, name, filename)
  File "/home/aaron/dev/grovr/venv/lib/python3.8/site-packages/jinja2/environment.py", line 638, in compile
    self.handle_exception(source=source_hint)
  File "/home/aaron/dev/grovr/venv/lib/python3.8/site-packages/jinja2/environment.py", line 832, in handle_exception
    reraise(*rewrite_traceback_stack(source=source))
  File "/home/aaron/dev/grovr/venv/lib/python3.8/site-packages/jinja2/_compat.py", line 28, in reraise
    raise value.with_traceback(tb)
  File "/home/aaron/dev/grovr/app/templates/user.html", line 13, in template
    {% elif not current_user.is_following(user) %}
jinja2.exceptions.TemplateSyntaxError: Encountered unknown tag 'elif'. Jinja was looking for the following tags: 'endblock'. The innermost block that needs to be closed is 'block'.
2021-04-10 17:10:32,196 ERROR: Exception on /user/nina [GET] [in /home/aaron/dev/grovr/venv/lib/python3.8/site-packages/flask/app.py:1891]
Traceback (most recent call last):
  File "/home/aaron/dev/grovr/venv/lib/python3.8/site-packages/flask/app.py", line 2447, in wsgi_app
    response = self.full_dispatch_request()
  File "/home/aaron/dev/grovr/venv/lib/python3.8/site-packages/flask/app.py", line 1952, in full_dispatch_request
    rv = self.handle_user_exception(e)
  File "/home/aaron/dev/grovr/venv/lib/python3.8/site-packages/flask/app.py", line 1821, in handle_user_exception
    reraise(exc_type, exc_value, tb)
  File "/home/aaron/dev/grovr/venv/lib/python3.8/site-packages/flask/_compat.py", line 39, in reraise
    raise value
  File "/home/aaron/dev/grovr/venv/lib/python3.8/site-packages/flask/app.py", line 1950, in full_dispatch_request
    rv = self.dispatch_request()
  File "/home/aaron/dev/grovr/venv/lib/python3.8/site-packages/flask/app.py", line 1936, in dispatch_request
    return self.view_functions[rule.endpoint](**req.view_args)
  File "/home/aaron/dev/grovr/venv/lib/python3.8/site-packages/flask_login/utils.py", line 272, in decorated_view
    return func(*args, **kwargs)
  File "/home/aaron/dev/grovr/app/routes.py", line 79, in user
    return render_template('user.html', user=user, posts=posts)
  File "/home/aaron/dev/grovr/venv/lib/python3.8/site-packages/flask/templating.py", line 137, in render_template
    return _render(
  File "/home/aaron/dev/grovr/venv/lib/python3.8/site-packages/flask/templating.py", line 120, in _render
    rv = template.render(context)
  File "/home/aaron/dev/grovr/venv/lib/python3.8/site-packages/jinja2/environment.py", line 1090, in render
    self.environment.handle_exception()
  File "/home/aaron/dev/grovr/venv/lib/python3.8/site-packages/jinja2/environment.py", line 832, in handle_exception
    reraise(*rewrite_traceback_stack(source=source))
  File "/home/aaron/dev/grovr/venv/lib/python3.8/site-packages/jinja2/_compat.py", line 28, in reraise
    raise value.with_traceback(tb)
  File "/home/aaron/dev/grovr/app/templates/user.html", line 1, in top-level template code
    {% extends "base.html" %}
  File "/home/aaron/dev/grovr/app/templates/base.html", line 30, in top-level template code
    {% block content %}
  File "/home/aaron/dev/grovr/app/templates/user.html", line 15, in block "content"
    {{ form.hidden_tag() }}
  File "/home/aaron/dev/grovr/venv/lib/python3.8/site-packages/jinja2/environment.py", line 471, in getattr
    return getattr(obj, attribute)
jinja2.exceptions.UndefinedError: 'form' is undefined
2021-04-10 17:12:42,671 ERROR: Exception on /user/nina [GET] [in /home/aaron/dev/grovr/venv/lib/python3.8/site-packages/flask/app.py:1891]
Traceback (most recent call last):
  File "/home/aaron/dev/grovr/venv/lib/python3.8/site-packages/flask/app.py", line 2447, in wsgi_app
    response = self.full_dispatch_request()
  File "/home/aaron/dev/grovr/venv/lib/python3.8/site-packages/flask/app.py", line 1952, in full_dispatch_request
    rv = self.handle_user_exception(e)
  File "/home/aaron/dev/grovr/venv/lib/python3.8/site-packages/flask/app.py", line 1821, in handle_user_exception
    reraise(exc_type, exc_value, tb)
  File "/home/aaron/dev/grovr/venv/lib/python3.8/site-packages/flask/_compat.py", line 39, in reraise
    raise value
  File "/home/aaron/dev/grovr/venv/lib/python3.8/site-packages/flask/app.py", line 1950, in full_dispatch_request
    rv = self.dispatch_request()
  File "/home/aaron/dev/grovr/venv/lib/python3.8/site-packages/flask/app.py", line 1936, in dispatch_request
    return self.view_functions[rule.endpoint](**req.view_args)
  File "/home/aaron/dev/grovr/venv/lib/python3.8/site-packages/flask_login/utils.py", line 272, in decorated_view
    return func(*args, **kwargs)
  File "/home/aaron/dev/grovr/app/routes.py", line 79, in user
    form = EmptyForm()
  File "/home/aaron/dev/grovr/venv/lib/python3.8/site-packages/flask/templating.py", line 137, in render_template
    return _render(
  File "/home/aaron/dev/grovr/venv/lib/python3.8/site-packages/flask/templating.py", line 120, in _render
    rv = template.render(context)
  File "/home/aaron/dev/grovr/venv/lib/python3.8/site-packages/jinja2/environment.py", line 1090, in render
    self.environment.handle_exception()
  File "/home/aaron/dev/grovr/venv/lib/python3.8/site-packages/jinja2/environment.py", line 832, in handle_exception
    reraise(*rewrite_traceback_stack(source=source))
  File "/home/aaron/dev/grovr/venv/lib/python3.8/site-packages/jinja2/_compat.py", line 28, in reraise
    raise value.with_traceback(tb)
  File "/home/aaron/dev/grovr/app/templates/user.html", line 1, in top-level template code
    {% extends "base.html" %}
  File "/home/aaron/dev/grovr/app/templates/base.html", line 30, in top-level template code
    {% block content %}
  File "/home/aaron/dev/grovr/app/templates/user.html", line 15, in block "content"
    {{ form.hidden_tag() }}
  File "/home/aaron/dev/grovr/venv/lib/python3.8/site-packages/jinja2/environment.py", line 471, in getattr
    return getattr(obj, attribute)
jinja2.exceptions.UndefinedError: 'form' is undefined
2021-04-10 17:12:52,366 INFO: Grovr startup [in /home/aaron/dev/grovr/app/__init__.py:34]
2021-04-11 12:41:25,308 INFO: Grovr startup [in /home/aaron/dev/grovr/app/__init__.py:34]
