2021-04-11 12:41:30,544 ERROR: Exception on / [GET] [in /home/aaron/dev/grovr/venv/lib/python3.8/site-packages/flask/app.py:1891]
Traceback (most recent call last):
  File "/home/aaron/dev/grovr/venv/lib/python3.8/site-packages/flask/app.py", line 2447, in wsgi_app
    response = self.full_dispatch_request()
  File "/home/aaron/dev/grovr/venv/lib/python3.8/site-packages/flask/app.py", line 1952, in full_dispatch_request
    rv = self.handle_user_exception(e)
  File "/home/aaron/dev/grovr/venv/lib/python3.8/site-packages/flask/app.py", line 1821, in handle_user_exception
    reraise(exc_type, exc_value, tb)
  File "/home/aaron/dev/grovr/venv/lib/python3.8/site-packages/flask/_compat.py", line 39, in reraise
    raise value
  File "/home/aaron/dev/grovr/venv/lib/python3.8/site-packages/flask/app.py", line 1950, in full_dispatch_request
    rv = self.dispatch_request()
  File "/home/aaron/dev/grovr/venv/lib/python3.8/site-packages/flask/app.py", line 1936, in dispatch_request
    return self.view_functions[rule.endpoint](**req.view_args)
  File "/home/aaron/dev/grovr/venv/lib/python3.8/site-packages/flask_login/utils.py", line 272, in decorated_view
    return func(*args, **kwargs)
  File "/home/aaron/dev/grovr/app/routes.py", line 29, in index
    return render_template('index.html', title='Home - Grovr', posts=posts)
  File "/home/aaron/dev/grovr/venv/lib/python3.8/site-packages/flask/templating.py", line 137, in render_template
    return _render(
  File "/home/aaron/dev/grovr/venv/lib/python3.8/site-packages/flask/templating.py", line 120, in _render
    rv = template.render(context)
  File "/home/aaron/dev/grovr/venv/lib/python3.8/site-packages/jinja2/environment.py", line 1090, in render
    self.environment.handle_exception()
  File "/home/aaron/dev/grovr/venv/lib/python3.8/site-packages/jinja2/environment.py", line 832, in handle_exception
    reraise(*rewrite_traceback_stack(source=source))
  File "/home/aaron/dev/grovr/venv/lib/python3.8/site-packages/jinja2/_compat.py", line 28, in reraise
    raise value.with_traceback(tb)
  File "/home/aaron/dev/grovr/app/templates/index.html", line 1, in top-level template code
    {% extends 'base.html' %}
  File "/home/aaron/dev/grovr/app/templates/base.html", line 30, in top-level template code
    {% block content %}
  File "/home/aaron/dev/grovr/app/templates/index.html", line 6, in block "content"
    {{ form.hidden_tag() }}
  File "/home/aaron/dev/grovr/venv/lib/python3.8/site-packages/jinja2/environment.py", line 471, in getattr
    return getattr(obj, attribute)
jinja2.exceptions.UndefinedError: 'form' is undefined
2021-05-04 21:21:32,308 INFO: Grovr startup [in /Users/aaron/dev/grovr/app/__init__.py:34]
2021-05-04 21:21:49,765 ERROR: Exception on / [GET] [in /usr/local/lib/python3.9/site-packages/flask/app.py:1891]
Traceback (most recent call last):
  File "/usr/local/lib/python3.9/site-packages/flask/app.py", line 2447, in wsgi_app
    response = self.full_dispatch_request()
  File "/usr/local/lib/python3.9/site-packages/flask/app.py", line 1952, in full_dispatch_request
    rv = self.handle_user_exception(e)
  File "/usr/local/lib/python3.9/site-packages/flask/app.py", line 1821, in handle_user_exception
    reraise(exc_type, exc_value, tb)
  File "/usr/local/lib/python3.9/site-packages/flask/_compat.py", line 39, in reraise
    raise value
  File "/usr/local/lib/python3.9/site-packages/flask/app.py", line 1950, in full_dispatch_request
    rv = self.dispatch_request()
  File "/usr/local/lib/python3.9/site-packages/flask/app.py", line 1936, in dispatch_request
    return self.view_functions[rule.endpoint](**req.view_args)
  File "/usr/local/lib/python3.9/site-packages/flask_login/utils.py", line 272, in decorated_view
    return func(*args, **kwargs)
  File "/Users/aaron/dev/grovr/app/routes.py", line 36, in index
    return render_template('index.html', title='Home - Grovr', posts=posts)
  File "/usr/local/lib/python3.9/site-packages/flask/templating.py", line 137, in render_template
    return _render(
  File "/usr/local/lib/python3.9/site-packages/flask/templating.py", line 120, in _render
    rv = template.render(context)
  File "/usr/local/lib/python3.9/site-packages/jinja2/environment.py", line 1090, in render
    self.environment.handle_exception()
  File "/usr/local/lib/python3.9/site-packages/jinja2/environment.py", line 832, in handle_exception
    reraise(*rewrite_traceback_stack(source=source))
  File "/usr/local/lib/python3.9/site-packages/jinja2/_compat.py", line 28, in reraise
    raise value.with_traceback(tb)
  File "/Users/aaron/dev/grovr/app/templates/index.html", line 1, in top-level template code
    {% extends 'base.html' %}
  File "/Users/aaron/dev/grovr/app/templates/base.html", line 30, in top-level template code
    {% block content %}
  File "/Users/aaron/dev/grovr/app/templates/index.html", line 6, in block "content"
    {{ form.hidden_tag() }}
  File "/usr/local/lib/python3.9/site-packages/jinja2/environment.py", line 471, in getattr
    return getattr(obj, attribute)
jinja2.exceptions.UndefinedError: 'form' is undefined
2021-05-04 21:34:15,849 INFO: Grovr startup [in /Users/aaron/dev/grovr/app/__init__.py:34]
2021-05-04 21:34:23,311 ERROR: Exception on / [GET] [in /usr/local/lib/python3.9/site-packages/flask/app.py:1891]
Traceback (most recent call last):
  File "/usr/local/lib/python3.9/site-packages/flask/app.py", line 2447, in wsgi_app
    response = self.full_dispatch_request()
  File "/usr/local/lib/python3.9/site-packages/flask/app.py", line 1952, in full_dispatch_request
    rv = self.handle_user_exception(e)
  File "/usr/local/lib/python3.9/site-packages/flask/app.py", line 1821, in handle_user_exception
    reraise(exc_type, exc_value, tb)
  File "/usr/local/lib/python3.9/site-packages/flask/_compat.py", line 39, in reraise
    raise value
  File "/usr/local/lib/python3.9/site-packages/flask/app.py", line 1950, in full_dispatch_request
    rv = self.dispatch_request()
  File "/usr/local/lib/python3.9/site-packages/flask/app.py", line 1936, in dispatch_request
    return self.view_functions[rule.endpoint](**req.view_args)
  File "/usr/local/lib/python3.9/site-packages/flask_login/utils.py", line 272, in decorated_view
    return func(*args, **kwargs)
  File "/Users/aaron/dev/grovr/app/routes.py", line 26, in index
    posts = current_user.followed_posts().all()
  File "/usr/local/lib/python3.9/site-packages/werkzeug/local.py", line 347, in __getattr__
    return getattr(self._get_current_object(), name)
AttributeError: 'User' object has no attribute 'followed_posts'
2021-05-04 21:34:29,379 ERROR: Exception on /index [GET] [in /usr/local/lib/python3.9/site-packages/flask/app.py:1891]
Traceback (most recent call last):
  File "/usr/local/lib/python3.9/site-packages/flask/app.py", line 2447, in wsgi_app
    response = self.full_dispatch_request()
  File "/usr/local/lib/python3.9/site-packages/flask/app.py", line 1952, in full_dispatch_request
    rv = self.handle_user_exception(e)
  File "/usr/local/lib/python3.9/site-packages/flask/app.py", line 1821, in handle_user_exception
    reraise(exc_type, exc_value, tb)
  File "/usr/local/lib/python3.9/site-packages/flask/_compat.py", line 39, in reraise
    raise value
  File "/usr/local/lib/python3.9/site-packages/flask/app.py", line 1950, in full_dispatch_request
    rv = self.dispatch_request()
  File "/usr/local/lib/python3.9/site-packages/flask/app.py", line 1936, in dispatch_request
    return self.view_functions[rule.endpoint](**req.view_args)
  File "/usr/local/lib/python3.9/site-packages/flask_login/utils.py", line 272, in decorated_view
    return func(*args, **kwargs)
  File "/Users/aaron/dev/grovr/app/routes.py", line 26, in index
    posts = current_user.followed_posts().all()
  File "/usr/local/lib/python3.9/site-packages/werkzeug/local.py", line 347, in __getattr__
    return getattr(self._get_current_object(), name)
AttributeError: 'User' object has no attribute 'followed_posts'
2021-05-04 21:35:21,451 INFO: Grovr startup [in /Users/aaron/dev/grovr/app/__init__.py:34]
2021-05-04 21:37:18,740 INFO: Grovr startup [in /Users/aaron/dev/grovr/app/__init__.py:34]
2021-05-04 21:37:44,953 INFO: Grovr startup [in /Users/aaron/dev/grovr/app/__init__.py:34]
2021-05-04 21:48:03,190 INFO: Grovr startup [in /Users/aaron/dev/grovr/app/__init__.py:34]
2021-05-04 21:48:10,549 ERROR: Exception on /explore [GET] [in /usr/local/lib/python3.9/site-packages/flask/app.py:1891]
Traceback (most recent call last):
  File "/usr/local/lib/python3.9/site-packages/flask/app.py", line 2447, in wsgi_app
    response = self.full_dispatch_request()
  File "/usr/local/lib/python3.9/site-packages/flask/app.py", line 1952, in full_dispatch_request
    rv = self.handle_user_exception(e)
  File "/usr/local/lib/python3.9/site-packages/flask/app.py", line 1821, in handle_user_exception
    reraise(exc_type, exc_value, tb)
  File "/usr/local/lib/python3.9/site-packages/flask/_compat.py", line 39, in reraise
    raise value
  File "/usr/local/lib/python3.9/site-packages/flask/app.py", line 1950, in full_dispatch_request
    rv = self.dispatch_request()
  File "/usr/local/lib/python3.9/site-packages/flask/app.py", line 1936, in dispatch_request
    return self.view_functions[rule.endpoint](**req.view_args)
  File "/usr/local/lib/python3.9/site-packages/flask_login/utils.py", line 272, in decorated_view
    return func(*args, **kwargs)
  File "/Users/aaron/dev/grovr/app/routes.py", line 136, in explore
    posts = Post.query.order_by(Post.timestamp.desc()).all()
NameError: name 'Post' is not defined
